2019-01-25 00:32:36,380 ERROR: Exception on /callback/q [GET] [in c:\users\omer\desktop\apple2spotify\venv\lib\site-packages\flask\app.py:1761]
Traceback (most recent call last):
  File "c:\users\omer\desktop\apple2spotify\venv\lib\site-packages\flask\app.py", line 2292, in wsgi_app
    response = self.full_dispatch_request()
  File "c:\users\omer\desktop\apple2spotify\venv\lib\site-packages\flask\app.py", line 1815, in full_dispatch_request
    rv = self.handle_user_exception(e)
  File "c:\users\omer\desktop\apple2spotify\venv\lib\site-packages\flask\app.py", line 1718, in handle_user_exception
    reraise(exc_type, exc_value, tb)
  File "c:\users\omer\desktop\apple2spotify\venv\lib\site-packages\flask\_compat.py", line 35, in reraise
    raise value
  File "c:\users\omer\desktop\apple2spotify\venv\lib\site-packages\flask\app.py", line 1813, in full_dispatch_request
    rv = self.dispatch_request()
  File "c:\users\omer\desktop\apple2spotify\venv\lib\site-packages\flask\app.py", line 1799, in dispatch_request
    return self.view_functions[rule.endpoint](**req.view_args)
  File "C:\Users\omer\Desktop\Apple2Spotify\app\routes.py", line 105, in callback
    access_token = response_data["access_token"]
KeyError: 'access_token'
2019-01-25 00:36:18,698 INFO: Apple2Spotify startup [in C:\Users\omer\Desktop\Apple2Spotify\app\__init__.py:43]
2019-01-25 00:36:28,238 ERROR: Exception on /callback/q [GET] [in c:\users\omer\desktop\apple2spotify\venv\lib\site-packages\flask\app.py:1761]
Traceback (most recent call last):
  File "c:\users\omer\desktop\apple2spotify\venv\lib\site-packages\flask\app.py", line 2292, in wsgi_app
    response = self.full_dispatch_request()
  File "c:\users\omer\desktop\apple2spotify\venv\lib\site-packages\flask\app.py", line 1815, in full_dispatch_request
    rv = self.handle_user_exception(e)
  File "c:\users\omer\desktop\apple2spotify\venv\lib\site-packages\flask\app.py", line 1718, in handle_user_exception
    reraise(exc_type, exc_value, tb)
  File "c:\users\omer\desktop\apple2spotify\venv\lib\site-packages\flask\_compat.py", line 35, in reraise
    raise value
  File "c:\users\omer\desktop\apple2spotify\venv\lib\site-packages\flask\app.py", line 1813, in full_dispatch_request
    rv = self.dispatch_request()
  File "c:\users\omer\desktop\apple2spotify\venv\lib\site-packages\flask\app.py", line 1799, in dispatch_request
    return self.view_functions[rule.endpoint](**req.view_args)
  File "C:\Users\omer\Desktop\Apple2Spotify\app\routes.py", line 105, in callback
    access_token = response_data["access_token"]
KeyError: 'access_token'
2019-01-25 00:37:29,781 INFO: Apple2Spotify startup [in C:\Users\omer\Desktop\Apple2Spotify\app\__init__.py:43]
2019-01-25 00:37:36,012 ERROR: Exception on /callback/q [GET] [in c:\users\omer\desktop\apple2spotify\venv\lib\site-packages\flask\app.py:1761]
Traceback (most recent call last):
  File "c:\users\omer\desktop\apple2spotify\venv\lib\site-packages\flask\app.py", line 2292, in wsgi_app
    response = self.full_dispatch_request()
  File "c:\users\omer\desktop\apple2spotify\venv\lib\site-packages\flask\app.py", line 1815, in full_dispatch_request
    rv = self.handle_user_exception(e)
  File "c:\users\omer\desktop\apple2spotify\venv\lib\site-packages\flask\app.py", line 1718, in handle_user_exception
    reraise(exc_type, exc_value, tb)
  File "c:\users\omer\desktop\apple2spotify\venv\lib\site-packages\flask\_compat.py", line 35, in reraise
    raise value
  File "c:\users\omer\desktop\apple2spotify\venv\lib\site-packages\flask\app.py", line 1813, in full_dispatch_request
    rv = self.dispatch_request()
  File "c:\users\omer\desktop\apple2spotify\venv\lib\site-packages\flask\app.py", line 1799, in dispatch_request
    return self.view_functions[rule.endpoint](**req.view_args)
  File "C:\Users\omer\Desktop\Apple2Spotify\app\routes.py", line 98, in callback
    "redirect_uri": REDIRECT_URI
NameError: name 'REDIRECT_URI' is not defined
2019-01-25 00:38:11,863 INFO: Apple2Spotify startup [in C:\Users\omer\Desktop\Apple2Spotify\app\__init__.py:43]
2019-01-25 00:38:18,802 ERROR: Exception on /callback/q [GET] [in c:\users\omer\desktop\apple2spotify\venv\lib\site-packages\flask\app.py:1761]
Traceback (most recent call last):
  File "c:\users\omer\desktop\apple2spotify\venv\lib\site-packages\flask\app.py", line 2292, in wsgi_app
    response = self.full_dispatch_request()
  File "c:\users\omer\desktop\apple2spotify\venv\lib\site-packages\flask\app.py", line 1815, in full_dispatch_request
    rv = self.handle_user_exception(e)
  File "c:\users\omer\desktop\apple2spotify\venv\lib\site-packages\flask\app.py", line 1718, in handle_user_exception
    reraise(exc_type, exc_value, tb)
  File "c:\users\omer\desktop\apple2spotify\venv\lib\site-packages\flask\_compat.py", line 35, in reraise
    raise value
  File "c:\users\omer\desktop\apple2spotify\venv\lib\site-packages\flask\app.py", line 1813, in full_dispatch_request
    rv = self.dispatch_request()
  File "c:\users\omer\desktop\apple2spotify\venv\lib\site-packages\flask\app.py", line 1799, in dispatch_request
    return self.view_functions[rule.endpoint](**req.view_args)
  File "C:\Users\omer\Desktop\Apple2Spotify\app\routes.py", line 110, in callback
    after_token(access_token)
NameError: name 'after_token' is not defined
2019-01-25 00:38:57,767 INFO: Apple2Spotify startup [in C:\Users\omer\Desktop\Apple2Spotify\app\__init__.py:43]
2019-01-25 00:39:04,172 ERROR: Exception on /callback/q [GET] [in c:\users\omer\desktop\apple2spotify\venv\lib\site-packages\flask\app.py:1761]
Traceback (most recent call last):
  File "c:\users\omer\desktop\apple2spotify\venv\lib\site-packages\flask\app.py", line 2292, in wsgi_app
    response = self.full_dispatch_request()
  File "c:\users\omer\desktop\apple2spotify\venv\lib\site-packages\flask\app.py", line 1815, in full_dispatch_request
    rv = self.handle_user_exception(e)
  File "c:\users\omer\desktop\apple2spotify\venv\lib\site-packages\flask\app.py", line 1718, in handle_user_exception
    reraise(exc_type, exc_value, tb)
  File "c:\users\omer\desktop\apple2spotify\venv\lib\site-packages\flask\_compat.py", line 35, in reraise
    raise value
  File "c:\users\omer\desktop\apple2spotify\venv\lib\site-packages\flask\app.py", line 1813, in full_dispatch_request
    rv = self.dispatch_request()
  File "c:\users\omer\desktop\apple2spotify\venv\lib\site-packages\flask\app.py", line 1799, in dispatch_request
    return self.view_functions[rule.endpoint](**req.view_args)
  File "C:\Users\omer\Desktop\Apple2Spotify\app\routes.py", line 110, in callback
    Convert.after_token(access_token)
  File "C:\Users\omer\Desktop\Apple2Spotify\app\convert.py", line 101, in after_token
    combine, playlist_name = Convert.gethtml(Convert.PLAYLIST_URL)
  File "C:\Users\omer\Desktop\Apple2Spotify\app\convert.py", line 10, in gethtml
    res = requests.get(playlistURL)
  File "c:\users\omer\desktop\apple2spotify\venv\lib\site-packages\requests\api.py", line 75, in get
    return request('get', url, params=params, **kwargs)
  File "c:\users\omer\desktop\apple2spotify\venv\lib\site-packages\requests\api.py", line 60, in request
    return session.request(method=method, url=url, **kwargs)
  File "c:\users\omer\desktop\apple2spotify\venv\lib\site-packages\requests\sessions.py", line 519, in request
    prep = self.prepare_request(req)
  File "c:\users\omer\desktop\apple2spotify\venv\lib\site-packages\requests\sessions.py", line 462, in prepare_request
    hooks=merge_hooks(request.hooks, self.hooks),
  File "c:\users\omer\desktop\apple2spotify\venv\lib\site-packages\requests\models.py", line 313, in prepare
    self.prepare_url(url, params)
  File "c:\users\omer\desktop\apple2spotify\venv\lib\site-packages\requests\models.py", line 387, in prepare_url
    raise MissingSchema(error)
requests.exceptions.MissingSchema: Invalid URL '': No schema supplied. Perhaps you meant http://?
2019-01-25 00:41:43,496 INFO: Apple2Spotify startup [in C:\Users\omer\Desktop\Apple2Spotify\app\__init__.py:43]
2019-01-25 00:41:50,671 ERROR: Exception on /callback/q [GET] [in c:\users\omer\desktop\apple2spotify\venv\lib\site-packages\flask\app.py:1761]
Traceback (most recent call last):
  File "c:\users\omer\desktop\apple2spotify\venv\lib\site-packages\flask\app.py", line 2292, in wsgi_app
    response = self.full_dispatch_request()
  File "c:\users\omer\desktop\apple2spotify\venv\lib\site-packages\flask\app.py", line 1815, in full_dispatch_request
    rv = self.handle_user_exception(e)
  File "c:\users\omer\desktop\apple2spotify\venv\lib\site-packages\flask\app.py", line 1718, in handle_user_exception
    reraise(exc_type, exc_value, tb)
  File "c:\users\omer\desktop\apple2spotify\venv\lib\site-packages\flask\_compat.py", line 35, in reraise
    raise value
  File "c:\users\omer\desktop\apple2spotify\venv\lib\site-packages\flask\app.py", line 1813, in full_dispatch_request
    rv = self.dispatch_request()
  File "c:\users\omer\desktop\apple2spotify\venv\lib\site-packages\flask\app.py", line 1799, in dispatch_request
    return self.view_functions[rule.endpoint](**req.view_args)
  File "C:\Users\omer\Desktop\Apple2Spotify\app\routes.py", line 110, in callback
    Convert.after_token(access_token)
  File "C:\Users\omer\Desktop\Apple2Spotify\app\convert.py", line 102, in after_token
    combine, playlist_name = Convert.gethtml(Convert.PLAYLIST_URL)
AttributeError: type object 'Convert' has no attribute 'PLAYLIST_URL'
2019-01-25 00:42:28,759 INFO: Apple2Spotify startup [in C:\Users\omer\Desktop\Apple2Spotify\app\__init__.py:43]
